2020-12-16 02:01:25,504 - googleapiclient.discovery_cache - WARNING - file_cache is unavailable when using oauth2client >= 4.0.0 or google-auth
Traceback (most recent call last):
  File "/home/delusion/.local/lib/python3.8/site-packages/googleapiclient/discovery_cache/file_cache.py", line 33, in <module>
    from oauth2client.contrib.locked_file import LockedFile
ModuleNotFoundError: No module named 'oauth2client.contrib.locked_file'

During handling of the above exception, another exception occurred:

Traceback (most recent call last):
  File "/home/delusion/.local/lib/python3.8/site-packages/googleapiclient/discovery_cache/file_cache.py", line 37, in <module>
    from oauth2client.locked_file import LockedFile
ModuleNotFoundError: No module named 'oauth2client.locked_file'

During handling of the above exception, another exception occurred:

Traceback (most recent call last):
  File "/home/delusion/.local/lib/python3.8/site-packages/googleapiclient/discovery_cache/__init__.py", line 44, in autodetect
    from . import file_cache
  File "/home/delusion/.local/lib/python3.8/site-packages/googleapiclient/discovery_cache/file_cache.py", line 40, in <module>
    raise ImportError(
ImportError: file_cache is unavailable when using oauth2client >= 4.0.0 or google-auth
2020-12-16 02:05:22,142 - telegram.ext.updater - WARNING - Exiting immediately!
